Workbook
Name Slicer_Credit_History: #N/A
Name Slicer_Education: #N/A
Name Slicer_Gender: #N/A
Name Slicer_Married: #N/A
Name Slicer_Property_Area: #N/A
Name Slicer_Self_Employed: #N/A

Sheet Dashboard
A1: Loan Sales & Approval Insights Dashboard
A3: KPI Card | D3: KPI Summary
A4: Gender
A5: Education | D5: Approval Rate | H5: Avg. Loan Amount (Approved) | L5: Avg. Applicant Income | P5: Top Performing Property Area | T5: Credit History Effect
A6: Property Area | D6: =COUNTIF(Data!R2:R615,"1")/COUNTA(Data!R2:R615) -> 0.68729642 | H6: =AVERAGEIFS(Data!I2:I615,Data!R2:R615, "1") -> 140.53318 | L6: =AVERAGEIFS(Data!G2:G615,Data!R2:R615,"1") -> 5384.0687 | P6: =Summary!A29 -> Semiurban | T6: =COUNTIFS(Data!K:K,0,Data!R:R,"1")/COUNTIF(Data!K:K,0) -> 0.21621622
A7: Credit History
A8: Loan Status
A9: Household Income | D9: Quick Insights: Urban graduates lead in approval rates by 78%. Credit history boosts approval by 21.62%. Families with 2 dependents have higher approval rate - revealing them as the most creditworthy customer persona.
A10: Marital status
D11: Core Insights
M72: Customer Persona Heatmap - App. Rate by Education, Credit History & Area
N73: Rural | P73: Semiurban | R73: Urban
M74: Education | N74: No Credit | O74: Has Credit | P74: No Credit | Q74: Has Credit | R74: No Credit | S74: Has Credit
M75: Graduate | N75: 0.18181818 | O75: 0.73394495 | P75: 0.24137931 | Q75: 0.86708861 | R75: 0.25925926 | S75: 0.77777778
M76: Not Graduate | N76: 0.1 | O76: 0.65789474 | P76: 0.33333333 | Q76: 0.86486486 | R76: 0.14285714 | S76: 0.73076923
D90: Dashboard Created by | F90: Eveline Wasonga | | H90: | Updated: 23-Oct-2025 | Source: Kaggle.com, Loan_Train.csv

Sheet Data
A1: Loan_ID | B1: Gender | C1: Married | D1: Dependents | E1: Education | F1: Self_Employed | G1: Applicant Income | H1: Co-applicant Income | I1: Loan Amount | J1: Loan_Amount_Term | K1: Credit_History | L1: Property_Area | M1: Loan_Status | N1: Total Income | O1: Income Band | P1: Loan to Income Ratio | Q1: Loan Amount Band | R1: Approval Flag | S1: Area Code
A2: LP001002 | B2: Male | C2: No | D2: 0 | E2: Graduate | F2: No | G2: 5849 | H2: 0 | I2: 0 | J2: 360 | K2: 1 | L2: Urban | M2: Y | N2: =G2+H2 -> 5849 | O2: =IF(N2<4000,"Low", IF(N2<8000, "Medium", "High")) -> Medium | P2: =I2/N2 -> 0 | Q2: =IF(I2<100, "Small", IF(I2<200, "Medium", "Large")) -> Small | R2: =IF(M2="Y", 1*1, 1*0) -> 1 | S2: =IF(L2="Urban","1", IF(L2="Rural", "2", IF(L2="Semiurban","3"))) -> 1
A3: LP001003 | B3: Male | C3: Yes | D3: 1 | E3: Graduate | F3: No | G3: 4583 | H3: 1508 | I3: 128 | J3: 360 | K3: 1 | L3: Rural | M3: N | N3: =G3+H3 -> 6091 | O3: =IF(N3<4000,"Low", IF(N3<8000, "Medium", "High")) -> Medium | P3: =I3/N3 -> 0.021014612 | Q3: =IF(I3<100, "Small", IF(I3<200, "Medium", "Large")) -> Medium | R3: =IF(M3="Y", 1*1, 1*0) -> 0 | S3: =IF(L3="Urban","1", IF(L3="Rural", "2", IF(L3="Semiurban","3"))) -> 2
A4: LP001005 | B4: Male | C4: Yes | D4: 0 | E4: Graduate | F4: Yes | G4: 3000 | H4: 0 | I4: 66 | J4: 360 | K4: 1 | L4: Urban | M4: Y | N4: =G4+H4 -> 3000 | O4: =IF(N4<4000,"Low", IF(N4<8000, "Medium", "High")) -> Low | P4: =I4/N4 -> 0.022 | Q4: =IF(I4<100, "Small", IF(I4<200, "Medium", "Large")) -> Small | R4: =IF(M4="Y", 1*1, 1*0) -> 1 | S4: =IF(L4="Urban","1", IF(L4="Rural", "2", IF(L4="Semiurban","3"))) -> 1
A5: LP001006 | B5: Male | C5: Yes | D5: 0 | E5: Not Graduate | F5: No | G5: 2583 | H5: 2358 | I5: 120 | J5: 360 | K5: 1 | L5: Urban | M5: Y | N5: =G5+H5 -> 4941 | O5: =IF(N5<4000,"Low", IF(N5<8000, "Medium", "High")) -> Medium | P5: =I5/N5 -> 0.024286582 | Q5: =IF(I5<100, "Small", IF(I5<200, "Medium", "Large")) -> Medium | R5: =IF(M5="Y", 1*1, 1*0) -> 1 | S5: =IF(L5="Urban","1", IF(L5="Rural", "2", IF(L5="Semiurban","3"))) -> 1
A6: LP001008 | B6: Male | C6: No | D6: 0 | E6: Graduate | F6: No | G6: 6000 | H6: 0 | I6: 141 | J6: 360 | K6: 1 | L6: Urban | M6: Y | N6: =G6+H6 -> 6000 | O6: =IF(N6<4000,"Low", IF(N6<8000, "Medium", "High")) -> Medium | P6: =I6/N6 -> 0.0235 | Q6: =IF(I6<100, "Small", IF(I6<200, "Medium", "Large")) -> Medium | R6: =IF(M6="Y", 1*1, 1*0) -> 1 | S6: =IF(L6="Urban","1", IF(L6="Rural", "2", IF(L6="Semiurban","3"))) -> 1
A7: LP001011 | B7: Male | C7: Yes | D7: 2 | E7: Graduate | F7: Yes | G7: 5417 | H7: 4196 | I7: 267 | J7: 360 | K7: 1 | L7: Urban | M7: Y | N7: =G7+H7 -> 9613 | O7: =IF(N7<4000,"Low", IF(N7<8000, "Medium", "High")) -> High | P7: =I7/N7 -> 0.027774888 | Q7: =IF(I7<100, "Small", IF(I7<200, "Medium", "Large")) -> Large | R7: =IF(M7="Y", 1*1, 1*0) -> 1 | S7: =IF(L7="Urban","1", IF(L7="Rural", "2", IF(L7="Semiurban","3"))) -> 1
A8: LP001013 | B8: Male | C8: Yes | D8: 0 | E8: Not Graduate | F8: No | G8: 2333 | H8: 1516 | I8: 95 | J8: 360 | K8: 1 | L8: Urban | M8: Y | N8: =G8+H8 -> 3849 | O8: =IF(N8<4000,"Low", IF(N8<8000, "Medium", "High")) -> Low | P8: =I8/N8 -> 0.024681736 | Q8: =IF(I8<100, "Small", IF(I8<200, "Medium", "Large")) -> Small | R8: =IF(M8="Y", 1*1, 1*0) -> 1 | S8: =IF(L8="Urban","1", IF(L8="Rural", "2", IF(L8="Semiurban","3"))) -> 1
A9: LP001014 | B9: Male | C9: Yes | D9: 3 | E9: Graduate | F9: No | G9: 3036 | H9: 2504 | I9: 158 | J9: 360 | K9: 0 | L9: Semiurban | M9: N | N9: =G9+H9 -> 5540 | O9: =IF(N9<4000,"Low", IF(N9<8000, "Medium", "High")) -> Medium | P9: =I9/N9 -> 0.028519856 | Q9: =IF(I9<100, "Small", IF(I9<200, "Medium", "Large")) -> Medium | R9: =IF(M9="Y", 1*1, 1*0) -> 0 | S9: =IF(L9="Urban","1", IF(L9="Rural", "2", IF(L9="Semiurban","3"))) -> 3
A10: LP001018 | B10: Male | C10: Yes | D10: 2 | E10: Graduate | F10: No | G10: 4006 | H10: 1526 | I10: 168 | J10: 360 | K10: 1 | L10: Urban | M10: Y | N10: =G10+H10 -> 5532 | O10: =IF(N10<4000,"Low", IF(N10<8000, "Medium", "High")) -> Medium | P10: =I10/N10 -> 0.030368764 | Q10: =IF(I10<100, "Small", IF(I10<200, "Medium", "Large")) -> Medium | R10: =IF(M10="Y", 1*1, 1*0) -> 1 | S10: =IF(L10="Urban","1", IF(L10="Rural", "2", IF(L10="Semiurban","3"))) -> 1
A11: LP001020 | B11: Male | C11: Yes | D11: 1 | E11: Graduate | F11: No | G11: 12841 | H11: 10968 | I11: 349 | J11: 360 | K11: 1 | L11: Semiurban | M11: N | N11: =G11+H11 -> 23809 | O11: =IF(N11<4000,"Low", IF(N11<8000, "Medium", "High")) -> High | P11: =I11/N11 -> 0.014658322 | Q11: =IF(I11<100, "Small", IF(I11<200, "Medium", "Large")) -> Large | R11: =IF(M11="Y", 1*1, 1*0) -> 0 | S11: =IF(L11="Urban","1", IF(L11="Rural", "2", IF(L11="Semiurban","3"))) -> 3
A12: LP001024 | B12: Male | C12: Yes | D12: 2 | E12: Graduate | F12: No | G12: 3200 | H12: 700 | I12: 70 | J12: 360 | K12: 1 | L12: Urban | M12: Y | N12: =G12+H12 -> 3900 | O12: =IF(N12<4000,"Low", IF(N12<8000, "Medium", "High")) -> Low | P12: =I12/N12 -> 0.017948718 | Q12: =IF(I12<100, "Small", IF(I12<200, "Medium", "Large")) -> Small | R12: =IF(M12="Y", 1*1, 1*0) -> 1 | S12: =IF(L12="Urban","1", IF(L12="Rural", "2", IF(L12="Semiurban","3"))) -> 1
A13: LP001027 | B13: Male | C13: Yes | D13: 2 | E13: Graduate | F13: No | G13: 2500 | H13: 1840 | I13: 109 | J13: 360 | K13: 1 | L13: Urban | M13: Y | N13: =G13+H13 -> 4340 | O13: =IF(N13<4000,"Low", IF(N13<8000, "Medium", "High")) -> Medium | P13: =I13/N13 -> 0.025115207 | Q13: =IF(I13<100, "Small", IF(I13<200, "Medium", "Large")) -> Medium | R13: =IF(M13="Y", 1*1, 1*0) -> 1 | S13: =IF(L13="Urban","1", IF(L13="Rural", "2", IF(L13="Semiurban","3"))) -> 1
... A615: LP002990 | B615: Female | C615: No | D615: 0 | E615: Graduate | F615: Yes | G615: 4583 | H615: 0 | I615: 133 | J615: 360 | K615: 0 | L615: Semiurban | M615: N | N615: =G615+H615 -> 4583 | O615: =IF(N615<4000,"Low", IF(N615<8000, "Medium", "High")) -> Medium | P615: =I615/N615 -> 0.029020292 | Q615: =IF(I615<100, "Small", IF(I615<200, "Medium", "Large")) -> Medium | R615: =IF(M615="Y", 1*1, 1*0) -> 0 | S615: =IF(L615="Urban","1", IF(L615="Rural", "2", IF(L615="Semiurban","3"))) -> 3

Sheet Summary
A2: Loan approval rate by gender
A3: Row Labels | B3: Count of Approval Flag
A4: Female | B4: 0.19381107
A5: Male | B5: 0.80618893 | D5: Credit effect
A6: Grand Total | B6: 1 | C6: w/o | D6: =COUNTIFS(Data!K:K,0,Data!R:R,"1")/COUNTIF(Data!K:K,1) -> 0.047713718
C7: w | D7: =COUNTIFS(Data!K:K,0,Data!R:R,"1")/COUNTIF(Data!K:K,0) -> 0.21621622
A8: Loan approval rate by education | D8: =D6-D7 -> -0.1685025
A9: Row Labels | B9: Count of Approval Flag
A10: Graduate | B10: 0.78175896 | D10: Loan_Status | E10: (All)
A11: Not Graduate | B11: 0.21824104
A12: Grand Total | B12: 1 | D12: ApplicantIncome | E12: Average of Loan Amount | G12: Row Labels | H12: Count of Loan_ID | I12: Sum of Approval Flag | J12: Approval Rate
D13: 0-1999 | E13: 105.275 | G13: 0-1999 | H13: 40 | I13: 25 | J13: =GETPIVOTDATA("Sum of Approval Flag",$G$12,"Applicant Income",0)/GETPIVOTDATA("Count of Loan_ID",$G$12,"Applicant Income",0) -> 0.625
A14: Loan approval rate by marital status | D14: 2000-3999 | E14: 110.19588 | G14: 2000-3999 | H14: 291 | I14: 206 | J14: =GETPIVOTDATA("Sum of Approval Flag",$G$12,"Applicant Income",2000)/GETPIVOTDATA("Count of Loan_ID",$G$12,"Applicant Income",2000) -> 0.70790378
A15: Row Labels | B15: Count of Approval Flag | D15: 4000-5999 | E15: 139.39286 | G15: 4000-5999 | H15: 140 | I15: 96 | J15: =GETPIVOTDATA("Sum of Approval Flag",$G$12,"Applicant Income",4000)/GETPIVOTDATA("Count of Loan_ID",$G$12,"Applicant Income",4000) -> 0.68571429
A16: No | B16: 0.35016287 | D16: 6000-7999 | E16: 169.25424 | G16: 6000-7999 | H16: 59 | I16: 37 | J16: =GETPIVOTDATA("Sum of Approval Flag",$G$12,"Applicant Income",6000)/GETPIVOTDATA("Count of Loan_ID",$G$12,"Applicant Income",6000) -> 0.62711864
A17: Yes | B17: 0.64983713 | D17: 8000-9999 | E17: 212.44828 | G17: 8000-9999 | H17: 29 | I17: 23 | J17: =GETPIVOTDATA("Sum of Approval Flag",$G$12,"Applicant Income",8000)/GETPIVOTDATA("Count of Loan_ID",$G$12,"Applicant Income",8000) -> 0.79310345
A18: Grand Total | B18: 1 | D18: 10000-11999 | E18: 194.9375 | G18: 10000-11999 | H18: 16 | I18: 8 | J18: =GETPIVOTDATA("Sum of Approval Flag",$G$12,"Applicant Income",10000)/GETPIVOTDATA("Count of Loan_ID",$G$12,"Applicant Income",10000) -> 0.5
D19: 12000-13999 | E19: 253.42857 | G19: 12000-13999 | H19: 7 | I19: 4 | J19: =GETPIVOTDATA("Sum of Approval Flag",$G$12,"Applicant Income",12000)/GETPIVOTDATA("Count of Loan_ID",$G$12,"Applicant Income",12000) -> 0.57142857
A20: Loan approval rate by employment status | D20: 14000-15999 | E20: 211 | G20: 14000-15999 | H20: 8 | I20: 6 | J20: =GETPIVOTDATA("Sum of Approval Flag",$G$12,"Applicant Income",14000)/GETPIVOTDATA("Count of Loan_ID",$G$12,"Applicant Income",14000) -> 0.75
A21: Row Labels | B21: Count of Approval Flag | D21: 16000-17999 | E21: 212.25 | G21: 16000-17999 | H21: 8 | I21: 7 | J21: =GETPIVOTDATA("Sum of Approval Flag",$G$12,"Applicant Income",16000)/GETPIVOTDATA("Count of Loan_ID",$G$12,"Applicant Income",16000) -> 0.875
A22: No | B22: 0.86644951 | D22: 18000-19999 | E22: 448.75 | G22: 18000-19999 | H22: 4 | I22: 2 | J22: =GETPIVOTDATA("Sum of Approval Flag",$G$12,"Applicant Income",18000)/GETPIVOTDATA("Count of Loan_ID",$G$12,"Applicant Income",18000) -> 0.5
A23: Yes | B23: 0.13355049 | D23: 20000-21999 | E23: 402.5 | G23: 20000-21999 | H23: 4 | I23: 2 | J23: =GETPIVOTDATA("Sum of Approval Flag",$G$12,"Applicant Income",20000)/GETPIVOTDATA("Count of Loan_ID",$G$12,"Applicant Income",20000) -> 0.5
A24: Grand Total | B24: 1 | D24: 22000-23999 | E24: 370 | G24: 22000-23999 | H24: 1 | I24: 1 | J24: =GETPIVOTDATA("Sum of Approval Flag",$G$12,"Applicant Income",22000)/GETPIVOTDATA("Count of Loan_ID",$G$12,"Applicant Income",22000) -> 1
D25: 32000-33999 | E25: 260 | G25: 32000-33999 | H25: 1 | I25: 0 | J25: =GETPIVOTDATA("Sum of Approval Flag",$G$12,"Applicant Income",32000)/GETPIVOTDATA("Count of Loan_ID",$G$12,"Applicant Income",32000) -> 0
A26: Loan approval rate by property area | D26: 36000-37999 | E26: 152 | G26: 36000-37999 | H26: 1 | I26: 1 | J26: =GETPIVOTDATA("Sum of Approval Flag",$G$12,"Applicant Income",36000)/GETPIVOTDATA("Count of Loan_ID",$G$12,"Applicant Income",36000) -> 1
A27: Row Labels | B27: Count of Approval Flag | D27: 38000-39999 | E27: 360 | G27: 38000-39999 | H27: 2 | I27: 2 | J27: =GETPIVOTDATA("Sum of Approval Flag",$G$12,"Applicant Income",38000)/GETPIVOTDATA("Count of Loan_ID",$G$12,"Applicant Income",38000) -> 1
A28: Rural | B28: 0.29153094 | D28: 50000-51999 | E28: 700 | G28: 50000-51999 | H28: 1 | I28: 1 | J28: =GETPIVOTDATA("Sum of Approval Flag",$G$12,"Applicant Income",50000)/GETPIVOTDATA("Count of Loan_ID",$G$12,"Applicant Income",50000) -> 1
A29: Semiurban | B29: 0.37947883 | D29: 62000-63999 | E29: 490 | G29: 62000-63999 | H29: 1 | I29: 1 | J29: =GETPIVOTDATA("Sum of Approval Flag",$G$12,"Applicant Income",62000)/GETPIVOTDATA("Count of Loan_ID",$G$12,"Applicant Income",62000) -> 1
A30: Urban | B30: 0.32899023 | D30: 80000-81999 | E30: 360 | G30: 80000-81999 | H30: 1 | I30: 0 | J30: =GETPIVOTDATA("Sum of Approval Flag",$G$12,"Applicant Income",80000)/GETPIVOTDATA("Count of Loan_ID",$G$12,"Applicant Income",80000) -> 0
A31: Grand Total | B31: 1 | D31: Grand Total | E31: 141.16612 | G31: Grand Total | H31: 614 | I31: 422 | J31: =GETPIVOTDATA("Sum of Approval Flag",$G$12)/GETPIVOTDATA("Count of Loan_ID",$G$12) -> 0.68729642
B35: ApplicantIncome | C35: Average of Loan Amount | D35: Approval Rate
B36: 0-1999 | C36: 105.275 | D36: =GETPIVOTDATA("Sum of Approval Flag",$G$12,"Applicant Income",0)/GETPIVOTDATA("Count of Loan_ID",$G$12,"Applicant Income",0) -> 0.625
B37: 2000-3999 | C37: 110.19588 | D37: =GETPIVOTDATA("Sum of Approval Flag",$G$12,"Applicant Income",2000)/GETPIVOTDATA("Count of Loan_ID",$G$12,"Applicant Income",2000) -> 0.70790378
B38: 4000-5999 | C38: 139.39286 | D38: =GETPIVOTDATA("Sum of Approval Flag",$G$12,"Applicant Income",4000)/GETPIVOTDATA("Count of Loan_ID",$G$12,"Applicant Income",4000) -> 0.68571429
B39: 6000-7999 | C39: 169.25424 | D39: =GETPIVOTDATA("Sum of Approval Flag",$G$12,"Applicant Income",6000)/GETPIVOTDATA("Count of Loan_ID",$G$12,"Applicant Income",6000) -> 0.62711864
B40: 8000-9999 | C40: 212.44828 | D40: =GETPIVOTDATA("Sum of Approval Flag",$G$12,"Applicant Income",8000)/GETPIVOTDATA("Count of Loan_ID",$G$12,"Applicant Income",8000) -> 0.79310345
B41: 10000-11999 | C41: 194.9375 | D41: =GETPIVOTDATA("Sum of Approval Flag",$G$12,"Applicant Income",10000)/GETPIVOTDATA("Count of Loan_ID",$G$12,"Applicant Income",10000) -> 0.5
B42: 12000-13999 | C42: 253.42857 | D42: =GETPIVOTDATA("Sum of Approval Flag",$G$12,"Applicant Income",12000)/GETPIVOTDATA("Count of Loan_ID",$G$12,"Applicant Income",12000) -> 0.57142857
B43: 14000-15999 | C43: 211 | D43: =GETPIVOTDATA("Sum of Approval Flag",$G$12,"Applicant Income",14000)/GETPIVOTDATA("Count of Loan_ID",$G$12,"Applicant Income",14000) -> 0.75
B44: 16000-17999 | C44: 212.25 | D44: =GETPIVOTDATA("Sum of Approval Flag",$G$12,"Applicant Income",16000)/GETPIVOTDATA("Count of Loan_ID",$G$12,"Applicant Income",16000) -> 0.875
...

Sheet Charts
A3: Row Labels | B3: Average of Loan Amount | C3: Approval_Rate | E3: Row Labels | F3: Average of Approval Flag | G3: Average of Loan Amount
A4: Rural | B4: 147.15642 | C4: 0.61452514 | E4: Short Term | F4: 0.75 | G4: 101.83333
A5: Semiurban | B5: 142.38197 | C5: 0.76824034 | E5: Medium Term | F5: 0.6557377 | G5: 146.85246
A6: Urban | B6: 134.45545 | C6: 0.65841584 | E6: Long Term | F6: 0.68946396 | G6: 141.39741
A7: Grand Total | B7: 141.16612 | C7: 0.68729642 | E7: Grand Total | F7: 0.68729642 | G7: 141.16612
A11: Row Labels | B11: Avg. Loan Amount | C11: Approval-Rate | E11: Row Labels | F11: Average of Approval Flag
A12: No Credit History | B12: 143.32432 | C12: 0.21621622 | E12: Low | F12: 0.67832168
A13: Has Credit History | B13: 140.68986 | C13: 0.79125249 | E13: Medium | F13: 0.69230769
A14: Grand Total | B14: 141.16612 | C14: 0.68729642 | E14: High | F14: 0.68421053
E15: Grand Total | F15: 0.68729642
E18: Average of Approval Flag | F18: Customer Persona Heatmap - Approval Rate by Education, Credit History & Property Area
A19: Dependents | B19: Average of Loan Amount | C19: % of Approval | F19: Rural | H19: Semiurban | J19: Urban
A20: 0 | B20: 130.70833 | C20: 0.68611111 | E20: Row Labels | F20: No Credit History | G20: Has Credit History | H20: No Credit History | I20: Has Credit History | J20: No Credit History | K20: Has Credit History
A21: 1 | B21: 152.40196 | C21: 0.64705882 | E21: Graduate | F21: 0.18181818 | G21: 0.73394495 | H21: 0.24137931 | I21: 0.86708861 | J21: 0.25925926 | K21: 0.77777778
A22: 2 | B22: 145.76238 | C22: 0.75247525 | E22: Not Graduate | F22: 0.1 | G22: 0.65789474 | H22: 0.33333333 | I22: 0.86486486 | J22: 0.14285714 | K22: 0.73076923
A23: 3+ | B23: 183.41176 | C23: 0.64705882
A24: Grand Total | B24: 141.16612 | C24: 0.68729642
